Workbook

Sheet Leia_me
A1: IngressoData Brasil — Etapa 1: Excel Avançado
A2: Microinformática Aplicada (ILP590) — FATEC SP — Prof. Veríssimo — 2º/2026
A4: Fluxo da planilha
A5: 1. Base_Bruta: as 3 planilhas de vendas (SP, RJ e MG) empilhadas sem nenhum tratamento.
A6: 2. DePara_*: tabelas de padronização (células amarelas = entrada; podem ser editadas).
A7: 3. Tratamento: cada coluna é uma fórmula que limpa a Base_Bruta (PROCX, ARRUMAR, VALORNUMERO, DATA).
A8: 4. Auditoria: confere que nenhuma linha some e que não há erros de fórmula.
A9: 5. Resumo_KPIs: faturamento, ticket médio e % de público turista (SOMASES).
A11: Problemas de qualidade tratados
A12: • Datas em 3 formatos: dd/mm/aaaa (texto, SP), data do Excel (RJ) e aaaa-mm-dd (texto, MG).
A13: • Valores como texto "R$ 1.250,00" (SP) e "450,00" (MG) convertidos com VALORNUMERO.
A14: • Categorias com grafias diferentes (SHOW, Shows, Fest., Cine...) padronizadas via PROCX no De-Para.
... A21: Dados 100% simulados (gerador com seed fixa em 04-documentacao/scripts). Eventos e nomes são fictícios.

Sheet Base_Bruta
A1: ID_Venda | B1: Data_Venda | C1: Data_Evento | D1: Evento | E1: Categoria | F1: Cidade_Evento | G1: Tipo_Ingresso | H1: Qtd | I1: Valor_Unitario | J1: Canal | K1: Comprador_ID | L1: Cidade_Comprador | M1: UF_Comprador | N1: Pais_Comprador | O1: CEP_Comprador | P1: Arquivo_Origem
A2: SP-000682 | B2: 05/01/2025 | C2: 05/01/2025 | D2: Cinema Paulista - Sessões | E2: Cinema | F2: São Paulo | G2: Inteira | H2: 2 | I2: R$ 45,00 | J2: Site | K2: C00387 | L2: São Paulo | M2: SP | N2: Brasil | O2: 01336-567 | P2: vendas_SP.xlsx
A3: SP-000661 | B3: 06/01/2025 | C3: 06/01/2025 | D3: Cinema Paulista - Sessões | E3: Cine | F3: São Paulo | G3: Inteira | H3: 1 | I3: R$ 35,00 | J3: Site | K3: C01112 | L3: São Paulo | M3: SP | N3: brasil | O3: 01867-320 | P3: vendas_SP.xlsx
A4: SP-000694 | B4: 07/01/2025 | C4: 10/01/2025 | D4: Cinema Paulista - Sessões | E4: Sessão Cinema | F4: Sao Paulo | G4: Meia | H4: 2 | I4: R$ 22,50 | J4: Site | K4: C02052 | L4: São Paulo | M4: SP | N4: Brasil | O4: 01793-815 | P4: vendas_SP.xlsx
A5: SP-000695 | B5: 09/01/2025 | C5: 12/01/2025 | D5: Cinema Paulista - Sessões | E5: CINEMA | F5: São Paulo | G5: Inteira | H5: 2 | I5: R$ 40,00 | J5: App | K5: C00952 | L5: SÃO PAULO | M5: SP | N5: Brasil | O5: 01008-886 | P5: vendas_SP.xlsx
A6: SP-000624 | B6: 11/01/2025 | C6: 14/01/2025 | D6: Cinema Paulista - Sessões | E6: Cinema | F6: São Paulo | G6: Meia | H6: 1 | I6: R$ 15,00 | J6: Site | K6: C02204 | L6: São Paulo | M6: SP | N6: Brasil | O6: 01358-382 | P6: vendas_SP.xlsx
A7: SP-000641 | B7: 15/01/2025 | C7: 17/01/2025 | D7: Cinema Paulista - Sessões | E7: Cinema | F7: São Paulo | G7: Meia | H7: 1 | I7: R$ 15,00 | J7: Bilheteria | K7: C00508 | L7: São Paulo | M7: SP | N7: Brasil | O7: 01088-882 | P7: vendas_SP.xlsx
A8: SP-000653 | B8: 15/01/2025 | C8: 17/01/2025 | D8: Cinema Paulista - Sessões | E8: Sessão Cinema | F8: São Paulo | G8: Meia | H8: 4 | I8: R$ 22,50 | J8: Site | K8: C02010 | L8: São Paulo | M8: SP | N8: Brasil | O8: 01668-944 | P8: vendas_SP.xlsx
A9: SP-000632 | B9: 16/01/2025 | C9: 17/01/2025 | D9: Cinema Paulista - Sessões | E9: cinema | F9: São Paulo | G9: Meia | H9: 2 | I9: R$ 15,00 | J9: App | K9: C00115 | L9: São Paulo | M9: SP | N9: Brasil | O9: 01106-857 | P9: vendas_SP.xlsx
A10: SP-000765 | B10: 16/01/2025 | C10: 17/01/2025 | D10: Cinema Paulista - Sessões | E10: Cinema | F10: SÃO PAULO | G10: Inteira | H10: 1 | I10: R$ 45,00 | J10: App | K10: C01088 | L10: São Paulo | M10: SP | N10: BR | O10: 01316-427 | P10: vendas_SP.xlsx
A11: SP-000748 | B11: 17/01/2025 | C11: 20/01/2025 | D11: Cinema Paulista - Sessões | E11: cinema | F11: São Paulo | G11: Inteira | H11: 1 | I11: R$ 40,00 | J11: Site | K11: C01797 | L11: São Paulo | M11: SP | N11: Brasil | O11: 01538-731 | P11: vendas_SP.xlsx
A12: SP-000778 | B12: 18/01/2025 | C12: 21/01/2025 | D12: Cinema Paulista - Sessões | E12: Cinema | F12: São Paulo | G12: Inteira | H12: 1 | I12: R$ 35,00 | J12: Site | K12: C00890 | L12: SÃO PAULO | M12: SP | N12: Brasil | O12: 01092-912 | P12: vendas_SP.xlsx
A13: SP-000722 | B13: 20/01/2025 | C13: 23/01/2025 | D13: Cinema Paulista - Sessões | E13: Cinema | F13: Sao Paulo | G13: Inteira | H13: 1 | I13: R$ 35,00 | J13: Site | K13: C00083 | L13: São Paulo | M13: SP | N13: Brasil | O13: 01733-879 | P13: vendas_SP.xlsx
... A37: SP-000777 | B37: 13/03/2025 | C37: 13/03/2025 | D37: Cinema Paulista - Sessões | E37: Cinema | F37: São Paulo | G37: Inteira | H37: 1 | I37: R$ 45,00 | J37: Bilheteria | K37: C01072 | L37: São Paulo | M37: SP | N37: BR | O37: 01420-173 | P37: vendas_SP.xlsx
A38: SP-000757 | B38: 21/03/2025 | C38: 22/03/2025 | D38: Cinema Paulista - Sessões | E38: Cinema | F38: São Paulo | G38: Inteira | H38: 2 | I38: R$ 40,00 | J38: App | K38: C02421 | L38: Santiago | M38: ex | N38: Chile | P38: vendas_SP.xlsx
A39: SP-000775 | B39: 21/03/2025 | C39: 23/03/2025 | D39: Cinema Paulista - Sessões | E39: Cinema | F39: São Paulo | G39: Meia | H39: 1 | I39: R$ 15,00 | J39: App | K39: C00427 | L39: São Paulo | M39: SP | N39: Brasil | O39: 01470-966 | P39: vendas_SP.xlsx
A40: SP-000655 | B40: 29/03/2025 | C40: 31/03/2025 | D40: Cinema Paulista - Sessões | E40: Cine | F40: São Paulo | G40: Inteira | H40: 1 | I40: R$ 45,00 | J40: Site | K40: C01408 | L40: São Paulo | M40: SP | N40: Brasil | O40: 01280-060 | P40: vendas_SP.xlsx
A41: SP-000717 | B41: 29/03/2025 | C41: 31/03/2025 | D41: Cinema Paulista - Sessões | E41: Cinema | F41: São Paulo | G41: Meia | H41: 1 | I41: R$ 17,50 | J41: App | K41: C01473 | L41: SÃO PAULO | M41: sp | N41: Brasil | O41: 01202-141 | P41: vendas_SP.xlsx
A42: SP-000726 | B42: 29/03/2025 | C42: 29/03/2025 | D42: Cinema Paulista - Sessões | E42: Cinema | F42: São Paulo | G42: Inteira | H42: 3 | I42: R$ 50,00 | J42: App | K42: C01935 | L42: São Paulo | M42: SP | N42: Brasil | O42: 01981-964 | P42: vendas_SP.xlsx
A43: SP-000719 | B43: 10/04/2025 | C43: 13/04/2025 | D43: Cinema Paulista - Sessões | E43: Cinema | F43: São Paulo | G43: Inteira | H43: 1 | I43: R$ 30,00 | J43: Site | K43: C00272 | L43: São Paulo | M43: SP | N43: Brasil | O43: 01453-234 | P43: vendas_SP.xlsx
A44: SP-000740 | B44: 16/04/2025 | C44: 17/04/2025 | D44: Cinema Paulista - Sessões | E44: CINEMA | F44: São Paulo | G44: Meia | H44: 3 | I44: R$ 22,50 | J44: Site | K44: C01089 | L44: São Paulo | M44: SP | N44: BR | O44: 01323-932 | P44: vendas_SP.xlsx
A45: SP-000726 | B45: 29/03/2025 | C45: 29/03/2025 | D45: Cinema Paulista - Sessões | E45: Cinema | F45: São Paulo | G45: Inteira | H45: 3 | I45: R$ 50,00 | J45: App | K45: C01935 | L45: São Paulo | M45: SP | N45: Brasil | O45: 01981-964 | P45: vendas_SP.xlsx
A46: SP-000679 | B46: 18/04/2025 | C46: 18/04/2025 | D46: Cinema Paulista - Sessões | E46: Cinema | F46: São Paulo | G46: Inteira | H46: 1 | I46: R$ 45,00 | J46: Site | K46: C01708 | L46: são paulo | M46: SP | N46: brasil | O46: 01360-113 | P46: vendas_SP.xlsx
A47: SP-000638 | B47: 20/04/2025 | C47: 20/04/2025 | D47: Cinema Paulista - Sessões | E47: Cine | F47: São Paulo | G47: Inteira | H47: 2 | I47: R$ 35,00 | J47: Site | K47: C01469 | L47: SÃO PAULO | M47: SP | N47: Brasil | O47: 01846-126 | P47: vendas_SP.xlsx
A48: SP-000693 | B48: 21/04/2025 | C48: 23/04/2025 | D48: Cinema Paulista - Sessões | E48: Cinema | F48: São Paulo | G48: Inteira | H48: 1 | I48: R$ 35,00 | J48: App | K48: C00738 | L48: Sao Paulo | M48: SP | N48: Brasil | O48: 01792-806 | P48: vendas_SP.xlsx
A49: SP-000635 | B49: 23/04/2025 | C49: 25/04/2025 | D49: Cinema Paulista - Sessões | E49: CINEMA | F49: São Paulo | G49: Inteira | H49: 2 | I49: R$ 35,00 | J49: App | K49: C00334 | L49: São Paulo | M49: SP | N49: Brasil | O49: 01454-266 | P49: vendas_SP.xlsx
A50: SP-000687 | B50: 24/04/2025 | C50: 25/04/2025 | D50: Cinema Paulista - Sessões | E50: Cine | F50: SÃO PAULO | G50: Inteira | H50: 1 | I50: R$ 35,00 | J50: App | K50: C00794 | L50: São Paulo | M50: SP | N50: Brasil | O50: 01678-861 | P50: vendas_SP.xlsx
... A65: SP-000671 | B65: 07/05/2025 | C65: 08/05/2025 | D65: Cinema Paulista - Sessões | E65: Cinema | F65: SÃO PAULO | G65: Meia | H65: 3 | I65: R$ 15,00 | J65: App | K65: C01186 | L65: São Paulo | M65: SP | N65: Brasil | O65: 01795-139 | P65: vendas_SP.xlsx
A66: SP-000509 | B66: 08/06/2025 | C66: 04/10/2025 | D66: Turnê Internacional Pop - SP | E66: Show | F66: São Paulo | G66: Inteira | H66: 3 | J66: Site | K66: C01939 | L66: São Paulo | M66: SP | N66: brasil | O66: 01447-220 | P66: vendas_SP.xlsx
A67: SP-000581 | B67: 08/06/2025 | C67: 04/10/2025 | D67: Turnê Internacional Pop - SP | E67: SHOW | F67: São Paulo | G67: VIP | H67: 2 | I67: R$ 1.070,00 | J67: Bilheteria | K67: C00680 | L67: São Paulo | M67: SP | N67: Brasil | O67: 01008-502 | P67: vendas_SP.xlsx
A68: SP-000609 | B68: 08/06/2025 | C68: 04/10/2025 | D68: Turnê Internacional Pop - SP | E68: Shows | F68: São Paulo | G68: Inteira | H68: 2 | I68: R$ 555,00 | J68: Parceiro | K68: C01321 | L68: Goiania | M68: GO | N68: brasil | O68: 74176-427 | P68: vendas_SP.xlsx
A69: SP-000690 | B69: 08/06/2025 | C69: 09/06/2025 | D69: Cinema Paulista - Sessões | E69: Cinema | F69: Sao Paulo | G69: Inteira | H69: 1 | I69: R$ 45,00 | J69: App | K69: C02096 | L69: São Paulo | M69: SP | N69: Brasil | O69: 01079-436 | P69: vendas_SP.xlsx
A70: SP-000546 | B70: 09/06/2025 | C70: 04/10/2025 | D70: Turnê Internacional Pop - SP | E70: Show | F70: São Paulo | G70: Inteira | H70: 4 | I70: R$ 625,00 | J70: App | K70: C01501 | L70: Sao Paulo | M70: SP | N70: Brasil | O70: 01644-032 | P70: vendas_SP.xlsx
A71: SP-000580 | B71: 09/06/2025 | C71: 04/10/2025 | D71: Turnê Internacional Pop - SP | E71: show | F71: São Paulo | G71: Inteira | H71: 4 | I71: R$ 615,00 | J71: App | K71: C00508 | L71: são paulo | M71: SP | N71: Brasil | O71: 01088-882 | P71: vendas_SP.xlsx
A72: SP-000483 | B72: 10/06/2025 | C72: 04/10/2025 | D72: Turnê Internacional Pop - SP | E72: Show | F72: SÃO PAULO | G72: Inteira | H72: 2 | I72: R$ 545,00 | J72: Bilheteria | K72: C01518 | L72: São Paulo | M72: SP | N72: BR | O72: 01366-769 | P72: vendas_SP.xlsx
A73: SP-000499 | B73: 10/06/2025 | C73: 04/10/2025 | D73: Turnê Internacional Pop - SP | E73: Show | F73: São Paulo | G73: Meia | H73: 2 | I73: R$ 370,00 | J73: App | K73: C00783 | L73: buenos aires | M73: EX | N73: Argentina | P73: vendas_SP.xlsx
A74: SP-000605 | B74: 10/06/2025 | C74: 04/10/2025 | D74: Turnê Internacional Pop - SP | E74: SHOW | F74: SP - São Paulo | G74: Inteira | H74: 2 | I74: R$ 300,00 | J74: Site | K74: C02308 | L74: São Paulo | M74: SP | N74: Brasil | O74: 01282-401 | P74: vendas_SP.xlsx
A75: SP-000562 | B75: 11/06/2025 | C75: 04/10/2025 | D75: Turnê Internacional Pop - SP | E75: Show | F75: Sao Paulo | G75: Meia | H75: 2 | I75: R$ 212,50 | J75: Bilheteria | K75: C00966 | L75: Recife | M75: PE | N75: Brasil | O75: 50620-578 | P75: vendas_SP.xlsx
A76: SP-000592 | B76: 11/06/2025 | C76: 04/10/2025 | D76: Turnê Internacional Pop - SP | E76: Shows | F76: Sao Paulo | G76: Meia | H76: 1 | I76: R$ 127,50 | J76: Site | K76: C01246 | L76: São Paulo | M76: SP | N76: Brasil | O76: 01485-158 | P76: vendas_SP.xlsx
A77: SP-000718 | B77: 11/06/2025 | C77: 14/06/2025 | D77: Cinema Paulista - Sessões | E77: Cinema | F77: São Paulo | G77: Inteira | H77: 2 | I77: R$ 45,00 | J77: Site | K77: C02010 | L77: São Paulo | M77: SP | N77: Brasil | O77: 01668-944 | P77: vendas_SP.xlsx
...

Sheet Tratamento
A1: ID_Venda | B1: Data_Venda | C1: Data_Evento | D1: Evento | E1: Categoria | F1: Cidade_Evento | G1: Tipo_Ingresso | H1: Qtd | I1: Valor_Unitario | J1: Valor_Total | K1: Canal | L1: Comprador_ID | M1: Cidade_Comprador | N1: UF_Comprador | O1: Pais_Comprador | P1: Origem_Publico | Q1: Mes_Venda | R1: Duplicado | S1: Status | T1: Arquivo_Origem
A2: =IF(Base_Bruta!A2="","",Base_Bruta!A2) -> SP-000682 | B2: =IF($A2="","",IF(ISNUMBER(Base_Bruta!B2),Base_Bruta!B2,IF(MID(Base_Bruta!B2,5,1)="-",DATE(VALUE(LEFT(Base_Bruta!B2,4)),VALUE(MID(Base_Bruta!B2,6,2)),VALUE(RIGHT(Base_Bruta!B2,2))),DATE(VALUE(RIGHT(Base_Bruta!B2,4)),VALUE(MID(Base_Bruta!B2,4,2)),VALUE(LEFT(Base_Bruta!B2,2)))))) -> 45662 | C2: =IF($A2="","",IF(ISNUMBER(Base_Bruta!C2),Base_Bruta!C2,IF(MID(Base_Bruta!C2,5,1)="-",DATE(VALUE(LEFT(Base_Bruta!C2,4)),VALUE(MID(Base_Bruta!C2,6,2)),VALUE(RIGHT(Base_Bruta!C2,2))),DATE(VALUE(RIGHT(Base_Bruta!C2,4)),VALUE(MID(Base_Bruta!C2,4,2)),VALUE(LEFT(Base_Bruta!C2,2)))))) -> 45662 | D2: =IF($A2="","",TRIM(Base_Bruta!D2)) -> Cinema Paulista - Sessões | E2: =IF($A2="","",_xlfn.XLOOKUP(LOWER(TRIM(Base_Bruta!E2)),DePara_Categoria!$A$2:$A$9,DePara_Categoria!$B$2:$B$9,"REVISAR")) -> Cinema | F2: =IF($A2="","",_xlfn.XLOOKUP(LOWER(TRIM(Base_Bruta!F2)),DePara_Cidade!$A$2:$A$29,DePara_Cidade!$B$2:$B$29,"REVISAR")) -> São Paulo | G2: =IF($A2="","",TRIM(Base_Bruta!G2)) -> Inteira | H2: =IF($A2="","",IF(ISNUMBER(Base_Bruta!H2),Base_Bruta!H2,IFERROR(_xlfn.NUMBERVALUE(TRIM(SUBSTITUTE(Base_Bruta!H2,"R$","")),",","."),0))) -> 2 | I2: =IF($A2="","",IF(ISNUMBER(Base_Bruta!I2),Base_Bruta!I2,IFERROR(_xlfn.NUMBERVALUE(TRIM(SUBSTITUTE(Base_Bruta!I2,"R$","")),",","."),0))) -> 45 | J2: =IF($A2="","",H2*I2) -> 90 | K2: =IF($A2="","",TRIM(Base_Bruta!J2)) -> Site | L2: =IF($A2="","",TRIM(Base_Bruta!K2)) -> C00387 | M2: =IF($A2="","",_xlfn.XLOOKUP(LOWER(TRIM(Base_Bruta!L2)),DePara_Cidade!$A$2:$A$29,DePara_Cidade!$B$2:$B$29,"REVISAR")) -> São Paulo | N2: =IF($A2="","",UPPER(TRIM(Base_Bruta!M2))) -> SP | O2: =IF($A2="","",_xlfn.XLOOKUP(LOWER(TRIM(Base_Bruta!N2)),DePara_Pais!$A$2:$A$9,DePara_Pais!$B$2:$B$9,"REVISAR")) -> Brasil | P2: =IF($A2="","",IF(O2<>"Brasil","Turista Internacional",IF(M2=F2,"Local","Turista Nacional"))) -> Local | Q2: =IF($A2="","",DATE(YEAR(B2),MONTH(B2),1)) -> 45658 | R2: =IF($A2="","",IF(COUNTIF($A$2:$A2,$A2)>1,"Sim","Não")) -> Não | S2: =IF(A2="","Descartar - Linha vazia",IF(R2="Sim","Descartar - Duplicado",IF(OR(H2<=0,I2<=0),"Descartar - Qtd/Valor inválido","OK"))) -> OK | T2: =Base_Bruta!P2 -> vendas_SP.xlsx
A3: =IF(Base_Bruta!A3="","",Base_Bruta!A3) -> SP-000661 | B3: =IF($A3="","",IF(ISNUMBER(Base_Bruta!B3),Base_Bruta!B3,IF(MID(Base_Bruta!B3,5,1)="-",DATE(VALUE(LEFT(Base_Bruta!B3,4)),VALUE(MID(Base_Bruta!B3,6,2)),VALUE(RIGHT(Base_Bruta!B3,2))),DATE(VALUE(RIGHT(Base_Bruta!B3,4)),VALUE(MID(Base_Bruta!B3,4,2)),VALUE(LEFT(Base_Bruta!B3,2)))))) -> 45663 | C3: =IF($A3="","",IF(ISNUMBER(Base_Bruta!C3),Base_Bruta!C3,IF(MID(Base_Bruta!C3,5,1)="-",DATE(VALUE(LEFT(Base_Bruta!C3,4)),VALUE(MID(Base_Bruta!C3,6,2)),VALUE(RIGHT(Base_Bruta!C3,2))),DATE(VALUE(RIGHT(Base_Bruta!C3,4)),VALUE(MID(Base_Bruta!C3,4,2)),VALUE(LEFT(Base_Bruta!C3,2)))))) -> 45663 | D3: =IF($A3="","",TRIM(Base_Bruta!D3)) -> Cinema Paulista - Sessões | E3: =IF($A3="","",_xlfn.XLOOKUP(LOWER(TRIM(Base_Bruta!E3)),DePara_Categoria!$A$2:$A$9,DePara_Categoria!$B$2:$B$9,"REVISAR")) -> Cinema | F3: =IF($A3="","",_xlfn.XLOOKUP(LOWER(TRIM(Base_Bruta!F3)),DePara_Cidade!$A$2:$A$29,DePara_Cidade!$B$2:$B$29,"REVISAR")) -> São Paulo | G3: =IF($A3="","",TRIM(Base_Bruta!G3)) -> Inteira | H3: =IF($A3="","",IF(ISNUMBER(Base_Bruta!H3),Base_Bruta!H3,IFERROR(_xlfn.NUMBERVALUE(TRIM(SUBSTITUTE(Base_Bruta!H3,"R$","")),",","."),0))) -> 1 | I3: =IF($A3="","",IF(ISNUMBER(Base_Bruta!I3),Base_Bruta!I3,IFERROR(_xlfn.NUMBERVALUE(TRIM(SUBSTITUTE(Base_Bruta!I3,"R$","")),",","."),0))) -> 35 | J3: =IF($A3="","",H3*I3) -> 35 | K3: =IF($A3="","",TRIM(Base_Bruta!J3)) -> Site | L3: =IF($A3="","",TRIM(Base_Bruta!K3)) -> C01112 | M3: =IF($A3="","",_xlfn.XLOOKUP(LOWER(TRIM(Base_Bruta!L3)),DePara_Cidade!$A$2:$A$29,DePara_Cidade!$B$2:$B$29,"REVISAR")) -> São Paulo | N3: =IF($A3="","",UPPER(TRIM(Base_Bruta!M3))) -> SP | O3: =IF($A3="","",_xlfn.XLOOKUP(LOWER(TRIM(Base_Bruta!N3)),DePara_Pais!$A$2:$A$9,DePara_Pais!$B$2:$B$9,"REVISAR")) -> Brasil | P3: =IF($A3="","",IF(O3<>"Brasil","Turista Internacional",IF(M3=F3,"Local","Turista Nacional"))) -> Local | Q3: =IF($A3="","",DATE(YEAR(B3),MONTH(B3),1)) -> 45658 | R3: =IF($A3="","",IF(COUNTIF($A$2:$A3,$A3)>1,"Sim","Não")) -> Não | S3: =IF(A3="","Descartar - Linha vazia",IF(R3="Sim","Descartar - Duplicado",IF(OR(H3<=0,I3<=0),"Descartar - Qtd/Valor inválido","OK"))) -> OK | T3: =Base_Bruta!P3 -> vendas_SP.xlsx
A4: =IF(Base_Bruta!A4="","",Base_Bruta!A4) -> SP-000694 | B4: =IF($A4="","",IF(ISNUMBER(Base_Bruta!B4),Base_Bruta!B4,IF(MID(Base_Bruta!B4,5,1)="-",DATE(VALUE(LEFT(Base_Bruta!B4,4)),VALUE(MID(Base_Bruta!B4,6,2)),VALUE(RIGHT(Base_Bruta!B4,2))),DATE(VALUE(RIGHT(Base_Bruta!B4,4)),VALUE(MID(Base_Bruta!B4,4,2)),VALUE(LEFT(Base_Bruta!B4,2)))))) -> 45664 | C4: =IF($A4="","",IF(ISNUMBER(Base_Bruta!C4),Base_Bruta!C4,IF(MID(Base_Bruta!C4,5,1)="-",DATE(VALUE(LEFT(Base_Bruta!C4,4)),VALUE(MID(Base_Bruta!C4,6,2)),VALUE(RIGHT(Base_Bruta!C4,2))),DATE(VALUE(RIGHT(Base_Bruta!C4,4)),VALUE(MID(Base_Bruta!C4,4,2)),VALUE(LEFT(Base_Bruta!C4,2)))))) -> 45667 | D4: =IF($A4="","",TRIM(Base_Bruta!D4)) -> Cinema Paulista - Sessões | E4: =IF($A4="","",_xlfn.XLOOKUP(LOWER(TRIM(Base_Bruta!E4)),DePara_Categoria!$A$2:$A$9,DePara_Categoria!$B$2:$B$9,"REVISAR")) -> Cinema | F4: =IF($A4="","",_xlfn.XLOOKUP(LOWER(TRIM(Base_Bruta!F4)),DePara_Cidade!$A$2:$A$29,DePara_Cidade!$B$2:$B$29,"REVISAR")) -> São Paulo | G4: =IF($A4="","",TRIM(Base_Bruta!G4)) -> Meia | H4: =IF($A4="","",IF(ISNUMBER(Base_Bruta!H4),Base_Bruta!H4,IFERROR(_xlfn.NUMBERVALUE(TRIM(SUBSTITUTE(Base_Bruta!H4,"R$","")),",","."),0))) -> 2 | I4: =IF($A4="","",IF(ISNUMBER(Base_Bruta!I4),Base_Bruta!I4,IFERROR(_xlfn.NUMBERVALUE(TRIM(SUBSTITUTE(Base_Bruta!I4,"R$","")),",","."),0))) -> 22.5 | J4: =IF($A4="","",H4*I4) -> 45 | K4: =IF($A4="","",TRIM(Base_Bruta!J4)) -> Site | L4: =IF($A4="","",TRIM(Base_Bruta!K4)) -> C02052 | M4: =IF($A4="","",_xlfn.XLOOKUP(LOWER(TRIM(Base_Bruta!L4)),DePara_Cidade!$A$2:$A$29,DePara_Cidade!$B$2:$B$29,"REVISAR")) -> São Paulo | N4: =IF($A4="","",UPPER(TRIM(Base_Bruta!M4))) -> SP | O4: =IF($A4="","",_xlfn.XLOOKUP(LOWER(TRIM(Base_Bruta!N4)),DePara_Pais!$A$2:$A$9,DePara_Pais!$B$2:$B$9,"REVISAR")) -> Brasil | P4: =IF($A4="","",IF(O4<>"Brasil","Turista Internacional",IF(M4=F4,"Local","Turista Nacional"))) -> Local | Q4: =IF($A4="","",DATE(YEAR(B4),MONTH(B4),1)) -> 45658 | R4: =IF($A4="","",IF(COUNTIF($A$2:$A4,$A4)>1,"Sim","Não")) -> Não | S4: =IF(A4="","Descartar - Linha vazia",IF(R4="Sim","Descartar - Duplicado",IF(OR(H4<=0,I4<=0),"Descartar - Qtd/Valor inválido","OK"))) -> OK | T4: =Base_Bruta!P4 -> vendas_SP.xlsx
A5: =IF(Base_Bruta!A5="","",Base_Bruta!A5) -> SP-000695 | B5: =IF($A5="","",IF(ISNUMBER(Base_Bruta!B5),Base_Bruta!B5,IF(MID(Base_Bruta!B5,5,1)="-",DATE(VALUE(LEFT(Base_Bruta!B5,4)),VALUE(MID(Base_Bruta!B5,6,2)),VALUE(RIGHT(Base_Bruta!B5,2))),DATE(VALUE(RIGHT(Base_Bruta!B5,4)),VALUE(MID(Base_Bruta!B5,4,2)),VALUE(LEFT(Base_Bruta!B5,2)))))) -> 45666 | C5: =IF($A5="","",IF(ISNUMBER(Base_Bruta!C5),Base_Bruta!C5,IF(MID(Base_Bruta!C5,5,1)="-",DATE(VALUE(LEFT(Base_Bruta!C5,4)),VALUE(MID(Base_Bruta!C5,6,2)),VALUE(RIGHT(Base_Bruta!C5,2))),DATE(VALUE(RIGHT(Base_Bruta!C5,4)),VALUE(MID(Base_Bruta!C5,4,2)),VALUE(LEFT(Base_Bruta!C5,2)))))) -> 45669 | D5: =IF($A5="","",TRIM(Base_Bruta!D5)) -> Cinema Paulista - Sessões | E5: =IF($A5="","",_xlfn.XLOOKUP(LOWER(TRIM(Base_Bruta!E5)),DePara_Categoria!$A$2:$A$9,DePara_Categoria!$B$2:$B$9,"REVISAR")) -> Cinema | F5: =IF($A5="","",_xlfn.XLOOKUP(LOWER(TRIM(Base_Bruta!F5)),DePara_Cidade!$A$2:$A$29,DePara_Cidade!$B$2:$B$29,"REVISAR")) -> São Paulo | G5: =IF($A5="","",TRIM(Base_Bruta!G5)) -> Inteira | H5: =IF($A5="","",IF(ISNUMBER(Base_Bruta!H5),Base_Bruta!H5,IFERROR(_xlfn.NUMBERVALUE(TRIM(SUBSTITUTE(Base_Bruta!H5,"R$","")),",","."),0))) -> 2 | I5: =IF($A5="","",IF(ISNUMBER(Base_Bruta!I5),Base_Bruta!I5,IFERROR(_xlfn.NUMBERVALUE(TRIM(SUBSTITUTE(Base_Bruta!I5,"R$","")),",","."),0))) -> 40 | J5: =IF($A5="","",H5*I5) -> 80 | K5: =IF($A5="","",TRIM(Base_Bruta!J5)) -> App | L5: =IF($A5="","",TRIM(Base_Bruta!K5)) -> C00952 | M5: =IF($A5="","",_xlfn.XLOOKUP(LOWER(TRIM(Base_Bruta!L5)),DePara_Cidade!$A$2:$A$29,DePara_Cidade!$B$2:$B$29,"REVISAR")) -> São Paulo | N5: =IF($A5="","",UPPER(TRIM(Base_Bruta!M5))) -> SP | O5: =IF($A5="","",_xlfn.XLOOKUP(LOWER(TRIM(Base_Bruta!N5)),DePara_Pais!$A$2:$A$9,DePara_Pais!$B$2:$B$9,"REVISAR")) -> Brasil | P5: =IF($A5="","",IF(O5<>"Brasil","Turista Internacional",IF(M5=F5,"Local","Turista Nacional"))) -> Local | Q5: =IF($A5="","",DATE(YEAR(B5),MONTH(B5),1)) -> 45658 | R5: =IF($A5="","",IF(COUNTIF($A$2:$A5,$A5)>1,"Sim","Não")) -> Não | S5: =IF(A5="","Descartar - Linha vazia",IF(R5="Sim","Descartar - Duplicado",IF(OR(H5<=0,I5<=0),"Descartar - Qtd/Valor inválido","OK"))) -> OK | T5: =Base_Bruta!P5 -> vendas_SP.xlsx
A6: =IF(Base_Bruta!A6="","",Base_Bruta!A6) -> SP-000624 | B6: =IF($A6="","",IF(ISNUMBER(Base_Bruta!B6),Base_Bruta!B6,IF(MID(Base_Bruta!B6,5,1)="-",DATE(VALUE(LEFT(Base_Bruta!B6,4)),VALUE(MID(Base_Bruta!B6,6,2)),VALUE(RIGHT(Base_Bruta!B6,2))),DATE(VALUE(RIGHT(Base_Bruta!B6,4)),VALUE(MID(Base_Bruta!B6,4,2)),VALUE(LEFT(Base_Bruta!B6,2)))))) -> 45668 | C6: =IF($A6="","",IF(ISNUMBER(Base_Bruta!C6),Base_Bruta!C6,IF(MID(Base_Bruta!C6,5,1)="-",DATE(VALUE(LEFT(Base_Bruta!C6,4)),VALUE(MID(Base_Bruta!C6,6,2)),VALUE(RIGHT(Base_Bruta!C6,2))),DATE(VALUE(RIGHT(Base_Bruta!C6,4)),VALUE(MID(Base_Bruta!C6,4,2)),VALUE(LEFT(Base_Bruta!C6,2)))))) -> 45671 | D6: =IF($A6="","",TRIM(Base_Bruta!D6)) -> Cinema Paulista - Sessões | E6: =IF($A6="","",_xlfn.XLOOKUP(LOWER(TRIM(Base_Bruta!E6)),DePara_Categoria!$A$2:$A$9,DePara_Categoria!$B$2:$B$9,"REVISAR")) -> Cinema | F6: =IF($A6="","",_xlfn.XLOOKUP(LOWER(TRIM(Base_Bruta!F6)),DePara_Cidade!$A$2:$A$29,DePara_Cidade!$B$2:$B$29,"REVISAR")) -> São Paulo | G6: =IF($A6="","",TRIM(Base_Bruta!G6)) -> Meia | H6: =IF($A6="","",IF(ISNUMBER(Base_Bruta!H6),Base_Bruta!H6,IFERROR(_xlfn.NUMBERVALUE(TRIM(SUBSTITUTE(Base_Bruta!H6,"R$","")),",","."),0))) -> 1 | I6: =IF($A6="","",IF(ISNUMBER(Base_Bruta!I6),Base_Bruta!I6,IFERROR(_xlfn.NUMBERVALUE(TRIM(SUBSTITUTE(Base_Bruta!I6,"R$","")),",","."),0))) -> 15 | J6: =IF($A6="","",H6*I6) -> 15 | K6: =IF($A6="","",TRIM(Base_Bruta!J6)) -> Site | L6: =IF($A6="","",TRIM(Base_Bruta!K6)) -> C02204 | M6: =IF($A6="","",_xlfn.XLOOKUP(LOWER(TRIM(Base_Bruta!L6)),DePara_Cidade!$A$2:$A$29,DePara_Cidade!$B$2:$B$29,"REVISAR")) -> São Paulo | N6: =IF($A6="","",UPPER(TRIM(Base_Bruta!M6))) -> SP | O6: =IF($A6="","",_xlfn.XLOOKUP(LOWER(TRIM(Base_Bruta!N6)),DePara_Pais!$A$2:$A$9,DePara_Pais!$B$2:$B$9,"REVISAR")) -> Brasil | P6: =IF($A6="","",IF(O6<>"Brasil","Turista Internacional",IF(M6=F6,"Local","Turista Nacional"))) -> Local | Q6: =IF($A6="","",DATE(YEAR(B6),MONTH(B6),1)) -> 45658 | R6: =IF($A6="","",IF(COUNTIF($A$2:$A6,$A6)>1,"Sim","Não")) -> Não | S6: =IF(A6="","Descartar - Linha vazia",IF(R6="Sim","Descartar - Duplicado",IF(OR(H6<=0,I6<=0),"Descartar - Qtd/Valor inválido","OK"))) -> OK | T6: =Base_Bruta!P6 -> vendas_SP.xlsx
A7: =IF(Base_Bruta!A7="","",Base_Bruta!A7) -> SP-000641 | B7: =IF($A7="","",IF(ISNUMBER(Base_Bruta!B7),Base_Bruta!B7,IF(MID(Base_Bruta!B7,5,1)="-",DATE(VALUE(LEFT(Base_Bruta!B7,4)),VALUE(MID(Base_Bruta!B7,6,2)),VALUE(RIGHT(Base_Bruta!B7,2))),DATE(VALUE(RIGHT(Base_Bruta!B7,4)),VALUE(MID(Base_Bruta!B7,4,2)),VALUE(LEFT(Base_Bruta!B7,2)))))) -> 45672 | C7: =IF($A7="","",IF(ISNUMBER(Base_Bruta!C7),Base_Bruta!C7,IF(MID(Base_Bruta!C7,5,1)="-",DATE(VALUE(LEFT(Base_Bruta!C7,4)),VALUE(MID(Base_Bruta!C7,6,2)),VALUE(RIGHT(Base_Bruta!C7,2))),DATE(VALUE(RIGHT(Base_Bruta!C7,4)),VALUE(MID(Base_Bruta!C7,4,2)),VALUE(LEFT(Base_Bruta!C7,2)))))) -> 45674 | D7: =IF($A7="","",TRIM(Base_Bruta!D7)) -> Cinema Paulista - Sessões | E7: =IF($A7="","",_xlfn.XLOOKUP(LOWER(TRIM(Base_Bruta!E7)),DePara_Categoria!$A$2:$A$9,DePara_Categoria!$B$2:$B$9,"REVISAR")) -> Cinema | F7: =IF($A7="","",_xlfn.XLOOKUP(LOWER(TRIM(Base_Bruta!F7)),DePara_Cidade!$A$2:$A$29,DePara_Cidade!$B$2:$B$29,"REVISAR")) -> São Paulo | G7: =IF($A7="","",TRIM(Base_Bruta!G7)) -> Meia | H7: =IF($A7="","",IF(ISNUMBER(Base_Bruta!H7),Base_Bruta!H7,IFERROR(_xlfn.NUMBERVALUE(TRIM(SUBSTITUTE(Base_Bruta!H7,"R$","")),",","."),0))) -> 1 | I7: =IF($A7="","",IF(ISNUMBER(Base_Bruta!I7),Base_Bruta!I7,IFERROR(_xlfn.NUMBERVALUE(TRIM(SUBSTITUTE(Base_Bruta!I7,"R$","")),",","."),0))) -> 15 | J7: =IF($A7="","",H7*I7) -> 15 | K7: =IF($A7="","",TRIM(Base_Bruta!J7)) -> Bilheteria | L7: =IF($A7="","",TRIM(Base_Bruta!K7)) -> C00508 | M7: =IF($A7="","",_xlfn.XLOOKUP(LOWER(TRIM(Base_Bruta!L7)),DePara_Cidade!$A$2:$A$29,DePara_Cidade!$B$2:$B$29,"REVISAR")) -> São Paulo | N7: =IF($A7="","",UPPER(TRIM(Base_Bruta!M7))) -> SP | O7: =IF($A7="","",_xlfn.XLOOKUP(LOWER(TRIM(Base_Bruta!N7)),DePara_Pais!$A$2:$A$9,DePara_Pais!$B$2:$B$9,"REVISAR")) -> Brasil | P7: =IF($A7="","",IF(O7<>"Brasil","Turista Internacional",IF(M7=F7,"Local","Turista Nacional"))) -> Local | Q7: =IF($A7="","",DATE(YEAR(B7),MONTH(B7),1)) -> 45658 | R7: =IF($A7="","",IF(COUNTIF($A$2:$A7,$A7)>1,"Sim","Não")) -> Não | S7: =IF(A7="","Descartar - Linha vazia",IF(R7="Sim","Descartar - Duplicado",IF(OR(H7<=0,I7<=0),"Descartar - Qtd/Valor inválido","OK"))) -> OK | T7: =Base_Bruta!P7 -> vendas_SP.xlsx
A8: =IF(Base_Bruta!A8="","",Base_Bruta!A8) -> SP-000653 | B8: =IF($A8="","",IF(ISNUMBER(Base_Bruta!B8),Base_Bruta!B8,IF(MID(Base_Bruta!B8,5,1)="-",DATE(VALUE(LEFT(Base_Bruta!B8,4)),VALUE(MID(Base_Bruta!B8,6,2)),VALUE(RIGHT(Base_Bruta!B8,2))),DATE(VALUE(RIGHT(Base_Bruta!B8,4)),VALUE(MID(Base_Bruta!B8,4,2)),VALUE(LEFT(Base_Bruta!B8,2)))))) -> 45672 | C8: =IF($A8="","",IF(ISNUMBER(Base_Bruta!C8),Base_Bruta!C8,IF(MID(Base_Bruta!C8,5,1)="-",DATE(VALUE(LEFT(Base_Bruta!C8,4)),VALUE(MID(Base_Bruta!C8,6,2)),VALUE(RIGHT(Base_Bruta!C8,2))),DATE(VALUE(RIGHT(Base_Bruta!C8,4)),VALUE(MID(Base_Bruta!C8,4,2)),VALUE(LEFT(Base_Bruta!C8,2)))))) -> 45674 | D8: =IF($A8="","",TRIM(Base_Bruta!D8)) -> Cinema Paulista - Sessões | E8: =IF($A8="","",_xlfn.XLOOKUP(LOWER(TRIM(Base_Bruta!E8)),DePara_Categoria!$A$2:$A$9,DePara_Categoria!$B$2:$B$9,"REVISAR")) -> Cinema | F8: =IF($A8="","",_xlfn.XLOOKUP(LOWER(TRIM(Base_Bruta!F8)),DePara_Cidade!$A$2:$A$29,DePara_Cidade!$B$2:$B$29,"REVISAR")) -> São Paulo | G8: =IF($A8="","",TRIM(Base_Bruta!G8)) -> Meia | H8: =IF($A8="","",IF(ISNUMBER(Base_Bruta!H8),Base_Bruta!H8,IFERROR(_xlfn.NUMBERVALUE(TRIM(SUBSTITUTE(Base_Bruta!H8,"R$","")),",","."),0))) -> 4 | I8: =IF($A8="","",IF(ISNUMBER(Base_Bruta!I8),Base_Bruta!I8,IFERROR(_xlfn.NUMBERVALUE(TRIM(SUBSTITUTE(Base_Bruta!I8,"R$","")),",","."),0))) -> 22.5 | J8: =IF($A8="","",H8*I8) -> 90 | K8: =IF($A8="","",TRIM(Base_Bruta!J8)) -> Site | L8: =IF($A8="","",TRIM(Base_Bruta!K8)) -> C02010 | M8: =IF($A8="","",_xlfn.XLOOKUP(LOWER(TRIM(Base_Bruta!L8)),DePara_Cidade!$A$2:$A$29,DePara_Cidade!$B$2:$B$29,"REVISAR")) -> São Paulo | N8: =IF($A8="","",UPPER(TRIM(Base_Bruta!M8))) -> SP | O8: =IF($A8="","",_xlfn.XLOOKUP(LOWER(TRIM(Base_Bruta!N8)),DePara_Pais!$A$2:$A$9,DePara_Pais!$B$2:$B$9,"REVISAR")) -> Brasil | P8: =IF($A8="","",IF(O8<>"Brasil","Turista Internacional",IF(M8=F8,"Local","Turista Nacional"))) -> Local | Q8: =IF($A8="","",DATE(YEAR(B8),MONTH(B8),1)) -> 45658 | R8: =IF($A8="","",IF(COUNTIF($A$2:$A8,$A8)>1,"Sim","Não")) -> Não | S8: =IF(A8="","Descartar - Linha vazia",IF(R8="Sim","Descartar - Duplicado",IF(OR(H8<=0,I8<=0),"Descartar - Qtd/Valor inválido","OK"))) -> OK | T8: =Base_Bruta!P8 -> vendas_SP.xlsx
A9: =IF(Base_Bruta!A9="","",Base_Bruta!A9) -> SP-000632 | B9: =IF($A9="","",IF(ISNUMBER(Base_Bruta!B9),Base_Bruta!B9,IF(MID(Base_Bruta!B9,5,1)="-",DATE(VALUE(LEFT(Base_Bruta!B9,4)),VALUE(MID(Base_Bruta!B9,6,2)),VALUE(RIGHT(Base_Bruta!B9,2))),DATE(VALUE(RIGHT(Base_Bruta!B9,4)),VALUE(MID(Base_Bruta!B9,4,2)),VALUE(LEFT(Base_Bruta!B9,2)))))) -> 45673 | C9: =IF($A9="","",IF(ISNUMBER(Base_Bruta!C9),Base_Bruta!C9,IF(MID(Base_Bruta!C9,5,1)="-",DATE(VALUE(LEFT(Base_Bruta!C9,4)),VALUE(MID(Base_Bruta!C9,6,2)),VALUE(RIGHT(Base_Bruta!C9,2))),DATE(VALUE(RIGHT(Base_Bruta!C9,4)),VALUE(MID(Base_Bruta!C9,4,2)),VALUE(LEFT(Base_Bruta!C9,2)))))) -> 45674 | D9: =IF($A9="","",TRIM(Base_Bruta!D9)) -> Cinema Paulista - Sessões | E9: =IF($A9="","",_xlfn.XLOOKUP(LOWER(TRIM(Base_Bruta!E9)),DePara_Categoria!$A$2:$A$9,DePara_Categoria!$B$2:$B$9,"REVISAR")) -> Cinema | F9: =IF($A9="","",_xlfn.XLOOKUP(LOWER(TRIM(Base_Bruta!F9)),DePara_Cidade!$A$2:$A$29,DePara_Cidade!$B$2:$B$29,"REVISAR")) -> São Paulo | G9: =IF($A9="","",TRIM(Base_Bruta!G9)) -> Meia | H9: =IF($A9="","",IF(ISNUMBER(Base_Bruta!H9),Base_Bruta!H9,IFERROR(_xlfn.NUMBERVALUE(TRIM(SUBSTITUTE(Base_Bruta!H9,"R$","")),",","."),0))) -> 2 | I9: =IF($A9="","",IF(ISNUMBER(Base_Bruta!I9),Base_Bruta!I9,IFERROR(_xlfn.NUMBERVALUE(TRIM(SUBSTITUTE(Base_Bruta!I9,"R$","")),",","."),0))) -> 15 | J9: =IF($A9="","",H9*I9) -> 30 | K9: =IF($A9="","",TRIM(Base_Bruta!J9)) -> App | L9: =IF($A9="","",TRIM(Base_Bruta!K9)) -> C00115 | M9: =IF($A9="","",_xlfn.XLOOKUP(LOWER(TRIM(Base_Bruta!L9)),DePara_Cidade!$A$2:$A$29,DePara_Cidade!$B$2:$B$29,"REVISAR")) -> São Paulo | N9: =IF($A9="","",UPPER(TRIM(Base_Bruta!M9))) -> SP | O9: =IF($A9="","",_xlfn.XLOOKUP(LOWER(TRIM(Base_Bruta!N9)),DePara_Pais!$A$2:$A$9,DePara_Pais!$B$2:$B$9,"REVISAR")) -> Brasil | P9: =IF($A9="","",IF(O9<>"Brasil","Turista Internacional",IF(M9=F9,"Local","Turista Nacional"))) -> Local | Q9: =IF($A9="","",DATE(YEAR(B9),MONTH(B9),1)) -> 45658 | R9: =IF($A9="","",IF(COUNTIF($A$2:$A9,$A9)>1,"Sim","Não")) -> Não | S9: =IF(A9="","Descartar - Linha vazia",IF(R9="Sim","Descartar - Duplicado",IF(OR(H9<=0,I9<=0),"Descartar - Qtd/Valor inválido","OK"))) -> OK | T9: =Base_Bruta!P9 -> vendas_SP.xlsx
A10: =IF(Base_Bruta!A10="","",Base_Bruta!A10) -> SP-000765 | B10: =IF($A10="","",IF(ISNUMBER(Base_Bruta!B10),Base_Bruta!B10,IF(MID(Base_Bruta!B10,5,1)="-",DATE(VALUE(LEFT(Base_Bruta!B10,4)),VALUE(MID(Base_Bruta!B10,6,2)),VALUE(RIGHT(Base_Bruta!B10,2))),DATE(VALUE(RIGHT(Base_Bruta!B10,4)),VALUE(MID(Base_Bruta!B10,4,2)),VALUE(LEFT(Base_Bruta!B10,2)))))) -> 45673 | C10: =IF($A10="","",IF(ISNUMBER(Base_Bruta!C10),Base_Bruta!C10,IF(MID(Base_Bruta!C10,5,1)="-",DATE(VALUE(LEFT(Base_Bruta!C10,4)),VALUE(MID(Base_Bruta!C10,6,2)),VALUE(RIGHT(Base_Bruta!C10,2))),DATE(VALUE(RIGHT(Base_Bruta!C10,4)),VALUE(MID(Base_Bruta!C10,4,2)),VALUE(LEFT(Base_Bruta!C10,2)))))) -> 45674 | D10: =IF($A10="","",TRIM(Base_Bruta!D10)) -> Cinema Paulista - Sessões | E10: =IF($A10="","",_xlfn.XLOOKUP(LOWER(TRIM(Base_Bruta!E10)),DePara_Categoria!$A$2:$A$9,DePara_Categoria!$B$2:$B$9,"REVISAR")) -> Cinema | F10: =IF($A10="","",_xlfn.XLOOKUP(LOWER(TRIM(Base_Bruta!F10)),DePara_Cidade!$A$2:$A$29,DePara_Cidade!$B$2:$B$29,"REVISAR")) -> São Paulo | G10: =IF($A10="","",TRIM(Base_Bruta!G10)) -> Inteira | H10: =IF($A10="","",IF(ISNUMBER(Base_Bruta!H10),Base_Bruta!H10,IFERROR(_xlfn.NUMBERVALUE(TRIM(SUBSTITUTE(Base_Bruta!H10,"R$","")),",","."),0))) -> 1 | I10: =IF($A10="","",IF(ISNUMBER(Base_Bruta!I10),Base_Bruta!I10,IFERROR(_xlfn.NUMBERVALUE(TRIM(SUBSTITUTE(Base_Bruta!I10,"R$","")),",","."),0))) -> 45 | J10: =IF($A10="","",H10*I10) -> 45 | K10: =IF($A10="","",TRIM(Base_Bruta!J10)) -> App | L10: =IF($A10="","",TRIM(Base_Bruta!K10)) -> C01088 | M10: =IF($A10="","",_xlfn.XLOOKUP(LOWER(TRIM(Base_Bruta!L10)),DePara_Cidade!$A$2:$A$29,DePara_Cidade!$B$2:$B$29,"REVISAR")) -> São Paulo | N10: =IF($A10="","",UPPER(TRIM(Base_Bruta!M10))) -> SP | O10: =IF($A10="","",_xlfn.XLOOKUP(LOWER(TRIM(Base_Bruta!N10)),DePara_Pais!$A$2:$A$9,DePara_Pais!$B$2:$B$9,"REVISAR")) -> Brasil | P10: =IF($A10="","",IF(O10<>"Brasil","Turista Internacional",IF(M10=F10,"Local","Turista Nacional"))) -> Local | Q10: =IF($A10="","",DATE(YEAR(B10),MONTH(B10),1)) -> 45658 | R10: =IF($A10="","",IF(COUNTIF($A$2:$A10,$A10)>1,"Sim","Não")) -> Não | S10: =IF(A10="","Descartar - Linha vazia",IF(R10="Sim","Descartar - Duplicado",IF(OR(H10<=0,I10<=0),"Descartar - Qtd/Valor inválido","OK"))) -> OK | T10: =Base_Bruta!P10 -> vendas_SP.xlsx
A11: =IF(Base_Bruta!A11="","",Base_Bruta!A11) -> SP-000748 | B11: =IF($A11="","",IF(ISNUMBER(Base_Bruta!B11),Base_Bruta!B11,IF(MID(Base_Bruta!B11,5,1)="-",DATE(VALUE(LEFT(Base_Bruta!B11,4)),VALUE(MID(Base_Bruta!B11,6,2)),VALUE(RIGHT(Base_Bruta!B11,2))),DATE(VALUE(RIGHT(Base_Bruta!B11,4)),VALUE(MID(Base_Bruta!B11,4,2)),VALUE(LEFT(Base_Bruta!B11,2)))))) -> 45674 | C11: =IF($A11="","",IF(ISNUMBER(Base_Bruta!C11),Base_Bruta!C11,IF(MID(Base_Bruta!C11,5,1)="-",DATE(VALUE(LEFT(Base_Bruta!C11,4)),VALUE(MID(Base_Bruta!C11,6,2)),VALUE(RIGHT(Base_Bruta!C11,2))),DATE(VALUE(RIGHT(Base_Bruta!C11,4)),VALUE(MID(Base_Bruta!C11,4,2)),VALUE(LEFT(Base_Bruta!C11,2)))))) -> 45677 | D11: =IF($A11="","",TRIM(Base_Bruta!D11)) -> Cinema Paulista - Sessões | E11: =IF($A11="","",_xlfn.XLOOKUP(LOWER(TRIM(Base_Bruta!E11)),DePara_Categoria!$A$2:$A$9,DePara_Categoria!$B$2:$B$9,"REVISAR")) -> Cinema | F11: =IF($A11="","",_xlfn.XLOOKUP(LOWER(TRIM(Base_Bruta!F11)),DePara_Cidade!$A$2:$A$29,DePara_Cidade!$B$2:$B$29,"REVISAR")) -> São Paulo | G11: =IF($A11="","",TRIM(Base_Bruta!G11)) -> Inteira | H11: =IF($A11="","",IF(ISNUMBER(Base_Bruta!H11),Base_Bruta!H11,IFERROR(_xlfn.NUMBERVALUE(TRIM(SUBSTITUTE(Base_Bruta!H11,"R$","")),",","."),0))) -> 1 | I11: =IF($A11="","",IF(ISNUMBER(Base_Bruta!I11),Base_Bruta!I11,IFERROR(_xlfn.NUMBERVALUE(TRIM(SUBSTITUTE(Base_Bruta!I11,"R$","")),",","."),0))) -> 40 | J11: =IF($A11="","",H11*I11) -> 40 | K11: =IF($A11="","",TRIM(Base_Bruta!J11)) -> Site | L11: =IF($A11="","",TRIM(Base_Bruta!K11)) -> C01797 | M11: =IF($A11="","",_xlfn.XLOOKUP(LOWER(TRIM(Base_Bruta!L11)),DePara_Cidade!$A$2:$A$29,DePara_Cidade!$B$2:$B$29,"REVISAR")) -> São Paulo | N11: =IF($A11="","",UPPER(TRIM(Base_Bruta!M11))) -> SP | O11: =IF($A11="","",_xlfn.XLOOKUP(LOWER(TRIM(Base_Bruta!N11)),DePara_Pais!$A$2:$A$9,DePara_Pais!$B$2:$B$9,"REVISAR")) -> Brasil | P11: =IF($A11="","",IF(O11<>"Brasil","Turista Internacional",IF(M11=F11,"Local","Turista Nacional"))) -> Local | Q11: =IF($A11="","",DATE(YEAR(B11),MONTH(B11),1)) -> 45658 | R11: =IF($A11="","",IF(COUNTIF($A$2:$A11,$A11)>1,"Sim","Não")) -> Não | S11: =IF(A11="","Descartar - Linha vazia",IF(R11="Sim","Descartar - Duplicado",IF(OR(H11<=0,I11<=0),"Descartar - Qtd/Valor inválido","OK"))) -> OK | T11: =Base_Bruta!P11 -> vendas_SP.xlsx
A12: =IF(Base_Bruta!A12="","",Base_Bruta!A12) -> SP-000778 | B12: =IF($A12="","",IF(ISNUMBER(Base_Bruta!B12),Base_Bruta!B12,IF(MID(Base_Bruta!B12,5,1)="-",DATE(VALUE(LEFT(Base_Bruta!B12,4)),VALUE(MID(Base_Bruta!B12,6,2)),VALUE(RIGHT(Base_Bruta!B12,2))),DATE(VALUE(RIGHT(Base_Bruta!B12,4)),VALUE(MID(Base_Bruta!B12,4,2)),VALUE(LEFT(Base_Bruta!B12,2)))))) -> 45675 | C12: =IF($A12="","",IF(ISNUMBER(Base_Bruta!C12),Base_Bruta!C12,IF(MID(Base_Bruta!C12,5,1)="-",DATE(VALUE(LEFT(Base_Bruta!C12,4)),VALUE(MID(Base_Bruta!C12,6,2)),VALUE(RIGHT(Base_Bruta!C12,2))),DATE(VALUE(RIGHT(Base_Bruta!C12,4)),VALUE(MID(Base_Bruta!C12,4,2)),VALUE(LEFT(Base_Bruta!C12,2)))))) -> 45678 | D12: =IF($A12="","",TRIM(Base_Bruta!D12)) -> Cinema Paulista - Sessões | E12: =IF($A12="","",_xlfn.XLOOKUP(LOWER(TRIM(Base_Bruta!E12)),DePara_Categoria!$A$2:$A$9,DePara_Categoria!$B$2:$B$9,"REVISAR")) -> Cinema | F12: =IF($A12="","",_xlfn.XLOOKUP(LOWER(TRIM(Base_Bruta!F12)),DePara_Cidade!$A$2:$A$29,DePara_Cidade!$B$2:$B$29,"REVISAR")) -> São Paulo | G12: =IF($A12="","",TRIM(Base_Bruta!G12)) -> Inteira | H12: =IF($A12="","",IF(ISNUMBER(Base_Bruta!H12),Base_Bruta!H12,IFERROR(_xlfn.NUMBERVALUE(TRIM(SUBSTITUTE(Base_Bruta!H12,"R$","")),",","."),0))) -> 1 | I12: =IF($A12="","",IF(ISNUMBER(Base_Bruta!I12),Base_Bruta!I12,IFERROR(_xlfn.NUMBERVALUE(TRIM(SUBSTITUTE(Base_Bruta!I12,"R$","")),",","."),0))) -> 35 | J12: =IF($A12="","",H12*I12) -> 35 | K12: =IF($A12="","",TRIM(Base_Bruta!J12)) -> Site | L12: =IF($A12="","",TRIM(Base_Bruta!K12)) -> C00890 | M12: =IF($A12="","",_xlfn.XLOOKUP(LOWER(TRIM(Base_Bruta!L12)),DePara_Cidade!$A$2:$A$29,DePara_Cidade!$B$2:$B$29,"REVISAR")) -> São Paulo | N12: =IF($A12="","",UPPER(TRIM(Base_Bruta!M12))) -> SP | O12: =IF($A12="","",_xlfn.XLOOKUP(LOWER(TRIM(Base_Bruta!N12)),DePara_Pais!$A$2:$A$9,DePara_Pais!$B$2:$B$9,"REVISAR")) -> Brasil | P12: =IF($A12="","",IF(O12<>"Brasil","Turista Internacional",IF(M12=F12,"Local","Turista Nacional"))) -> Local | Q12: =IF($A12="","",DATE(YEAR(B12),MONTH(B12),1)) -> 45658 | R12: =IF($A12="","",IF(COUNTIF($A$2:$A12,$A12)>1,"Sim","Não")) -> Não | S12: =IF(A12="","Descartar - Linha vazia",IF(R12="Sim","Descartar - Duplicado",IF(OR(H12<=0,I12<=0),"Descartar - Qtd/Valor inválido","OK"))) -> OK | T12: =Base_Bruta!P12 -> vendas_SP.xlsx
A13: =IF(Base_Bruta!A13="","",Base_Bruta!A13) -> SP-000722 | B13: =IF($A13="","",IF(ISNUMBER(Base_Bruta!B13),Base_Bruta!B13,IF(MID(Base_Bruta!B13,5,1)="-",DATE(VALUE(LEFT(Base_Bruta!B13,4)),VALUE(MID(Base_Bruta!B13,6,2)),VALUE(RIGHT(Base_Bruta!B13,2))),DATE(VALUE(RIGHT(Base_Bruta!B13,4)),VALUE(MID(Base_Bruta!B13,4,2)),VALUE(LEFT(Base_Bruta!B13,2)))))) -> 45677 | C13: =IF($A13="","",IF(ISNUMBER(Base_Bruta!C13),Base_Bruta!C13,IF(MID(Base_Bruta!C13,5,1)="-",DATE(VALUE(LEFT(Base_Bruta!C13,4)),VALUE(MID(Base_Bruta!C13,6,2)),VALUE(RIGHT(Base_Bruta!C13,2))),DATE(VALUE(RIGHT(Base_Bruta!C13,4)),VALUE(MID(Base_Bruta!C13,4,2)),VALUE(LEFT(Base_Bruta!C13,2)))))) -> 45680 | D13: =IF($A13="","",TRIM(Base_Bruta!D13)) -> Cinema Paulista - Sessões | E13: =IF($A13="","",_xlfn.XLOOKUP(LOWER(TRIM(Base_Bruta!E13)),DePara_Categoria!$A$2:$A$9,DePara_Categoria!$B$2:$B$9,"REVISAR")) -> Cinema | F13: =IF($A13="","",_xlfn.XLOOKUP(LOWER(TRIM(Base_Bruta!F13)),DePara_Cidade!$A$2:$A$29,DePara_Cidade!$B$2:$B$29,"REVISAR")) -> São Paulo | G13: =IF($A13="","",TRIM(Base_Bruta!G13)) -> Inteira | H13: =IF($A13="","",IF(ISNUMBER(Base_Bruta!H13),Base_Bruta!H13,IFERROR(_xlfn.NUMBERVALUE(TRIM(SUBSTITUTE(Base_Bruta!H13,"R$","")),",","."),0))) -> 1 | I13: =IF($A13="","",IF(ISNUMBER(Base_Bruta!I13),Base_Bruta!I13,IFERROR(_xlfn.NUMBERVALUE(TRIM(SUBSTITUTE(Base_Bruta!I13,"R$","")),",","."),0))) -> 35 | J13: =IF($A13="","",H13*I13) -> 35 | K13: =IF($A13="","",TRIM(Base_Bruta!J13)) -> Site | L13: =IF($A13="","",TRIM(Base_Bruta!K13)) -> C00083 | M13: =IF($A13="","",_xlfn.XLOOKUP(LOWER(TRIM(Base_Bruta!L13)),DePara_Cidade!$A$2:$A$29,DePara_Cidade!$B$2:$B$29,"REVISAR")) -> São Paulo | N13: =IF($A13="","",UPPER(TRIM(Base_Bruta!M13))) -> SP | O13: =IF($A13="","",_xlfn.XLOOKUP(LOWER(TRIM(Base_Bruta!N13)),DePara_Pais!$A$2:$A$9,DePara_Pais!$B$2:$B$9,"REVISAR")) -> Brasil | P13: =IF($A13="","",IF(O13<>"Brasil","Turista Internacional",IF(M13=F13,"Local","Turista Nacional"))) -> Local | Q13: =IF($A13="","",DATE(YEAR(B13),MONTH(B13),1)) -> 45658 | R13: =IF($A13="","",IF(COUNTIF($A$2:$A13,$A13)>1,"Sim","Não")) -> Não | S13: =IF(A13="","Descartar - Linha vazia",IF(R13="Sim","Descartar - Duplicado",IF(OR(H13<=0,I13<=0),"Descartar - Qtd/Valor inválido","OK"))) -> OK | T13: =Base_Bruta!P13 -> vendas_SP.xlsx
... A2092: =IF(Base_Bruta!A2092="","",Base_Bruta!A2092) -> MG-000491 | B2092: =IF($A2092="","",IF(ISNUMBER(Base_Bruta!B2092),Base_Bruta!B2092,IF(MID(Base_Bruta!B2092,5,1)="-",DATE(VALUE(LEFT(Base_Bruta!B2092,4)),VALUE(MID(Base_Bruta!B2092,6,2)),VALUE(RIGHT(Base_Bruta!B2092,2))),DATE(VALUE(RIGHT(Base_Bruta!B2092,4)),VALUE(MID(Base_Bruta!B2092,4,2)),VALUE(LEFT(Base_Bruta!B2092,2)))))) -> 46203 | C2092: =IF($A2092="","",IF(ISNUMBER(Base_Bruta!C2092),Base_Bruta!C2092,IF(MID(Base_Bruta!C2092,5,1)="-",DATE(VALUE(LEFT(Base_Bruta!C2092,4)),VALUE(MID(Base_Bruta!C2092,6,2)),VALUE(RIGHT(Base_Bruta!C2092,2))),DATE(VALUE(RIGHT(Base_Bruta!C2092,4)),VALUE(MID(Base_Bruta!C2092,4,2)),VALUE(LEFT(Base_Bruta!C2092,2)))))) -> 46203 | D2092: =IF($A2092="","",TRIM(Base_Bruta!D2092)) -> Cinema Savassi - Sessões | E2092: =IF($A2092="","",_xlfn.XLOOKUP(LOWER(TRIM(Base_Bruta!E2092)),DePara_Categoria!$A$2:$A$9,DePara_Categoria!$B$2:$B$9,"REVISAR")) -> Cinema | F2092: =IF($A2092="","",_xlfn.XLOOKUP(LOWER(TRIM(Base_Bruta!F2092)),DePara_Cidade!$A$2:$A$29,DePara_Cidade!$B$2:$B$29,"REVISAR")) -> Belo Horizonte | G2092: =IF($A2092="","",TRIM(Base_Bruta!G2092)) -> Inteira | H2092: =IF($A2092="","",IF(ISNUMBER(Base_Bruta!H2092),Base_Bruta!H2092,IFERROR(_xlfn.NUMBERVALUE(TRIM(SUBSTITUTE(Base_Bruta!H2092,"R$","")),",","."),0))) -> 1 | I2092: =IF($A2092="","",IF(ISNUMBER(Base_Bruta!I2092),Base_Bruta!I2092,IFERROR(_xlfn.NUMBERVALUE(TRIM(SUBSTITUTE(Base_Bruta!I2092,"R$","")),",","."),0))) -> 30 | J2092: =IF($A2092="","",H2092*I2092) -> 30 | K2092: =IF($A2092="","",TRIM(Base_Bruta!J2092)) -> Site | L2092: =IF($A2092="","",TRIM(Base_Bruta!K2092)) -> C00215 | M2092: =IF($A2092="","",_xlfn.XLOOKUP(LOWER(TRIM(Base_Bruta!L2092)),DePara_Cidade!$A$2:$A$29,DePara_Cidade!$B$2:$B$29,"REVISAR")) -> Belo Horizonte | N2092: =IF($A2092="","",UPPER(TRIM(Base_Bruta!M2092))) -> MG | O2092: =IF($A2092="","",_xlfn.XLOOKUP(LOWER(TRIM(Base_Bruta!N2092)),DePara_Pais!$A$2:$A$9,DePara_Pais!$B$2:$B$9,"REVISAR")) -> Brasil | P2092: =IF($A2092="","",IF(O2092<>"Brasil","Turista Internacional",IF(M2092=F2092,"Local","Turista Nacional"))) -> Local | Q2092: =IF($A2092="","",DATE(YEAR(B2092),MONTH(B2092),1)) -> 46174 | R2092: =IF($A2092="","",IF(COUNTIF($A$2:$A2092,$A2092)>1,"Sim","Não")) -> Não | S2092: =IF(A2092="","Descartar - Linha vazia",IF(R2092="Sim","Descartar - Duplicado",IF(OR(H2092<=0,I2092<=0),"Descartar - Qtd/Valor inválido","OK"))) -> OK | T2092: =Base_Bruta!P2092 -> vendas_MG.csv

Sheet Auditoria
A1: Indicador de qualidade | B1: Valor | C1: Como é calculado
A2: Linhas na base bruta | B2: =COUNTA(Tratamento!T2:T2092) -> 2091 | C2: Todas as linhas empilhadas (inclui vazias)
A3: Linhas vazias | B3: =COUNTIF(Tratamento!S2:S2092,"Descartar - Linha vazia") -> 12 | C3: ID_Venda em branco
A4: Linhas duplicadas | B4: =COUNTIF(Tratamento!S2:S2092,"Descartar - Duplicado") -> 49 | C4: Mesmo ID_Venda já apareceu antes
A5: Qtd ou valor inválido | B5: =COUNTIF(Tratamento!S2:S2092,"Descartar - Qtd/Valor inválido") -> 30 | C5: Qtd ou valor vazio/zero
A6: Linhas válidas (OK) | B6: =COUNTIF(Tratamento!S2:S2092,"OK") -> 2000 | C6: Entram nos indicadores
A7: Conferência (bruta = descartes + OK) | B7: =IF(B2=SUM(B3:B6),"OK","DIVERGENTE") -> OK | C7: Nenhuma linha some sem explicação
A8: Valores sem De-Para (REVISAR) | B8: =COUNTIF(Tratamento!E2:O2092,"REVISAR") -> 0 | C8: Tem que ser 0
A9: Células com erro de fórmula | B9: =SUMPRODUCT(--ISERROR(Tratamento!A2:T2092)) -> 0 | C9: Tem que ser 0
A10: Status geral | B10: =IF(AND(B7="OK",B8=0,B9=0),"APROVADO","REVISAR") -> APROVADO | C10: Planilha sem erros e sem perdas

Sheet Resumo_KPIs
A1: IngressoData Brasil — Indicadores (somente linhas com Status OK)
A3: Categoria | B3: Faturamento | C3: Ingressos | D3: Ticket Médio | E3: Faturamento Turista | F3: % Faturamento Turista | G3: Participação no Faturamento
A4: Festival | B4: =SUMIFS(Tratamento!$J$2:$J$2092,Tratamento!$E$2:$E$2092,$A4,Tratamento!$S$2:$S$2092,"OK") -> 1460022.5 | C4: =SUMIFS(Tratamento!$H$2:$H$2092,Tratamento!$E$2:$E$2092,$A4,Tratamento!$S$2:$S$2092,"OK") -> 1725 | D4: =IF(C4=0,0,B4/C4) -> 846.38986 | E4: =SUMIFS(Tratamento!$J$2:$J$2092,Tratamento!$E$2:$E$2092,$A4,Tratamento!$S$2:$S$2092,"OK",Tratamento!$P$2:$P$2092,"<>Local") -> 656305 | F4: =IF(B4=0,0,E4/B4) -> 0.44951705 | G4: =IF($B$7=0,0,B4/$B$7) -> 0.7165359
A5: Show | B5: =SUMIFS(Tratamento!$J$2:$J$2092,Tratamento!$E$2:$E$2092,$A5,Tratamento!$S$2:$S$2092,"OK") -> 548412.5 | C5: =SUMIFS(Tratamento!$H$2:$H$2092,Tratamento!$E$2:$E$2092,$A5,Tratamento!$S$2:$S$2092,"OK") -> 1155 | D5: =IF(C5=0,0,B5/C5) -> 474.81602 | E5: =SUMIFS(Tratamento!$J$2:$J$2092,Tratamento!$E$2:$E$2092,$A5,Tratamento!$S$2:$S$2092,"OK",Tratamento!$P$2:$P$2092,"<>Local") -> 212807.5 | F5: =IF(B5=0,0,E5/B5) -> 0.38804276 | G5: =IF($B$7=0,0,B5/$B$7) -> 0.26914465
A6: Cinema | B6: =SUMIFS(Tratamento!$J$2:$J$2092,Tratamento!$E$2:$E$2092,$A6,Tratamento!$S$2:$S$2092,"OK") -> 29177.5 | C6: =SUMIFS(Tratamento!$H$2:$H$2092,Tratamento!$E$2:$E$2092,$A6,Tratamento!$S$2:$S$2092,"OK") -> 924 | D6: =IF(C6=0,0,B6/C6) -> 31.577381 | E6: =SUMIFS(Tratamento!$J$2:$J$2092,Tratamento!$E$2:$E$2092,$A6,Tratamento!$S$2:$S$2092,"OK",Tratamento!$P$2:$P$2092,"<>Local") -> 1757.5 | F6: =IF(B6=0,0,E6/B6) -> 0.06023477 | G6: =IF($B$7=0,0,B6/$B$7) -> 0.014319455
A7: Total | B7: =SUM(B4:B6) -> 2037612.5 | C7: =SUM(C4:C6) -> 3804 | D7: =IF(C7=0,0,B7/C7) -> 535.64997 | E7: =SUM(E4:E6) -> 870870 | F7: =IF(B7=0,0,E7/B7) -> 0.42739726 | G7: =SUM(G4:G6) -> 1
A10: Faturamento por praça e origem do público
A11: Praça | B11: Local | C11: Turista Nacional | D11: Turista Internacional | E11: Total | F11: % Turista
A12: São Paulo | B12: =SUMIFS(Tratamento!$J$2:$J$2092,Tratamento!$F$2:$F$2092,$A12,Tratamento!$P$2:$P$2092,B$11,Tratamento!$S$2:$S$2092,"OK") -> 493375 | C12: =SUMIFS(Tratamento!$J$2:$J$2092,Tratamento!$F$2:$F$2092,$A12,Tratamento!$P$2:$P$2092,C$11,Tratamento!$S$2:$S$2092,"OK") -> 290455 | D12: =SUMIFS(Tratamento!$J$2:$J$2092,Tratamento!$F$2:$F$2092,$A12,Tratamento!$P$2:$P$2092,D$11,Tratamento!$S$2:$S$2092,"OK") -> 74825 | E12: =SUM(B12:D12) -> 858655 | F12: =IF(E12=0,0,(C12+D12)/E12) -> 0.42540951
A13: Rio de Janeiro | B13: =SUMIFS(Tratamento!$J$2:$J$2092,Tratamento!$F$2:$F$2092,$A13,Tratamento!$P$2:$P$2092,B$11,Tratamento!$S$2:$S$2092,"OK") -> 374945 | C13: =SUMIFS(Tratamento!$J$2:$J$2092,Tratamento!$F$2:$F$2092,$A13,Tratamento!$P$2:$P$2092,C$11,Tratamento!$S$2:$S$2092,"OK") -> 240265 | D13: =SUMIFS(Tratamento!$J$2:$J$2092,Tratamento!$F$2:$F$2092,$A13,Tratamento!$P$2:$P$2092,D$11,Tratamento!$S$2:$S$2092,"OK") -> 48107.5 | E13: =SUM(B13:D13) -> 663317.5 | F13: =IF(E13=0,0,(C13+D13)/E13) -> 0.43474279
A14: Belo Horizonte | B14: =SUMIFS(Tratamento!$J$2:$J$2092,Tratamento!$F$2:$F$2092,$A14,Tratamento!$P$2:$P$2092,B$11,Tratamento!$S$2:$S$2092,"OK") -> 298422.5 | C14: =SUMIFS(Tratamento!$J$2:$J$2092,Tratamento!$F$2:$F$2092,$A14,Tratamento!$P$2:$P$2092,C$11,Tratamento!$S$2:$S$2092,"OK") -> 185712.5 | D14: =SUMIFS(Tratamento!$J$2:$J$2092,Tratamento!$F$2:$F$2092,$A14,Tratamento!$P$2:$P$2092,D$11,Tratamento!$S$2:$S$2092,"OK") -> 31505 | E14: =SUM(B14:D14) -> 515640 | F14: =IF(E14=0,0,(C14+D14)/E14) -> 0.42125805
A15: Total | B15: =SUM(B12:B14) -> 1166742.5 | C15: =SUM(C12:C14) -> 716432.5 | D15: =SUM(D12:D14) -> 154437.5 | E15: =SUM(E12:E14) -> 2037612.5 | F15: =IF(E15=0,0,(C15+D15)/E15) -> 0.42739726
A18: Indicadores gerais
A19: Indicador | B19: Valor
A20: Faturamento total | B20: =B7 -> 2037612.5
A21: Ingressos vendidos | B21: =C7 -> 3804
A22: Pedidos válidos | B22: =COUNTIF(Tratamento!$S$2:$S$2092,"OK") -> 2000
A23: Ticket médio por ingresso | B23: =D7 -> 535.64997
A24: Ticket médio por pedido | B24: =IF(B22=0,0,B20/B22) -> 1018.8062
A25: % do faturamento vindo de turistas | B25: =F7 -> 0.42739726

Sheet DePara_Categoria
A1: Original | B1: Padrao
A2: cine | B2: Cinema
A3: cinema | B3: Cinema
A4: fest. | B4: Festival
A5: festivais | B5: Festival
A6: festival | B6: Festival
A7: sessão cinema | B7: Cinema
A8: show | B8: Show
A9: shows | B9: Show

Sheet DePara_Cidade
A1: Original | B1: Padrao
A2: belo horizonte | B2: Belo Horizonte
A3: bh | B3: Belo Horizonte
A4: brasilia | B4: Brasília
A5: brasília | B5: Brasília
A6: buenos aires | B6: Buenos Aires
A7: campinas | B7: Campinas
A8: contagem | B8: Contagem
A9: curitiba | B9: Curitiba
A10: florianopolis | B10: Florianópolis
A11: florianópolis | B11: Florianópolis
A12: goiania | B12: Goiânia
... A29: vitória | B29: Vitória

Sheet DePara_Pais
A1: Original | B1: Padrao
A2: argentina | B2: Argentina
A3: br | B3: Brasil
A4: brasil | B4: Brasil
A5: chile | B5: Chile
A6: estados unidos | B6: EUA
A7: eua | B7: EUA
A8: portugal | B8: Portugal
A9: usa | B9: EUA

Sheet Cadastro_Eventos
A1: Evento | B1: Categoria | C1: Cidade_Evento | D1: Local | E1: Ao_Ar_Livre | F1: Data_Evento
A2: Festival Sonora SP 2025 | B2: Festival | C2: São Paulo | D2: Autódromo de Interlagos | E2: Sim | F2: 45976
A3: Festival Sonora SP 2026 | B3: Festival | C3: São Paulo | D3: Autódromo de Interlagos | E3: Sim | F3: 46130
A4: Rio Beat Festival 2026 | B4: Festival | C4: Rio de Janeiro | D4: Parque Olímpico | E4: Sim | F4: 46046
A5: Festival Montanhas BH 2025 | B5: Festival | C5: Belo Horizonte | D5: Esplanada do Mineirão | E5: Sim | F5: 45892
A6: Turnê Internacional Pop - SP | B6: Show | C6: São Paulo | D6: Estádio Allianz Parque | E6: Sim | F6: 45934
A7: Show Nacional MPB - Rio | B7: Show | C7: Rio de Janeiro | D7: Arena Jeunesse | E7: Não | F7: 45822
A8: Turnê Internacional Rock - Rio | B8: Show | C8: Rio de Janeiro | D8: Estádio Nilton Santos | E8: Sim | F8: 46151
A9: Show Sertanejo - BH | B9: Show | C9: Belo Horizonte | D9: Mineirão | E9: Sim | F9: 46081
A10: Cinema Paulista - Sessões | B10: Cinema | C10: São Paulo | D10: Cine Shopping Paulista | E10: Não
A11: Cinema Barra - Sessões | B11: Cinema | C11: Rio de Janeiro | D11: Cine Barra Shopping | E11: Não
A12: Cinema Savassi - Sessões | B12: Cinema | C12: Belo Horizonte | D12: Cine Savassi | E12: Não
